Traceback (most recent call last):
  File "C:\ProgramData\anaconda3\envs\MachineLearningBook\lib\site-packages\jupyter_cache\executors\utils.py", line 58, in single_nb_execution
    executenb(
  File "C:\ProgramData\anaconda3\envs\MachineLearningBook\lib\site-packages\nbclient\client.py", line 1305, in execute
    return NotebookClient(nb=nb, resources=resources, km=km, **kwargs).execute()
  File "C:\ProgramData\anaconda3\envs\MachineLearningBook\lib\site-packages\jupyter_core\utils\__init__.py", line 165, in wrapped
    return loop.run_until_complete(inner)
  File "C:\ProgramData\anaconda3\envs\MachineLearningBook\lib\asyncio\base_events.py", line 608, in run_until_complete
    return future.result()
  File "C:\ProgramData\anaconda3\envs\MachineLearningBook\lib\site-packages\nbclient\client.py", line 705, in async_execute
    await self.async_execute_cell(
  File "C:\ProgramData\anaconda3\envs\MachineLearningBook\lib\site-packages\nbclient\client.py", line 1058, in async_execute_cell
    await self._check_raise_for_error(cell, cell_index, exec_reply)
  File "C:\ProgramData\anaconda3\envs\MachineLearningBook\lib\site-packages\nbclient\client.py", line 914, in _check_raise_for_error
    raise CellExecutionError.from_cell_and_msg(cell, exec_reply_content)
nbclient.exceptions.CellExecutionError: An error occurred while executing the following cell:
------------------
os.chdir("c:/PGE383")             # set the working directory
------------------


[1;31m---------------------------------------------------------------------------[0m
[1;31mFileNotFoundError[0m                         Traceback (most recent call last)
Cell [1;32mIn[3], line 1[0m
[1;32m----> 1[0m [43mos[49m[38;5;241;43m.[39;49m[43mchdir[49m[43m([49m[38;5;124;43m"[39;49m[38;5;124;43mc:/PGE383[39;49m[38;5;124;43m"[39;49m[43m)[49m             [38;5;66;03m# set the working directory[39;00m

[1;31mFileNotFoundError[0m: [WinError 2] The system cannot find the file specified: 'c:/PGE383'

